2018-07-18 01:12:52,365 ERROR: Exception on /admin/category/import [POST] [in /home/kodi/anaconda3/lib/python3.6/site-packages/flask/app.py:1761]
Traceback (most recent call last):
  File "/home/kodi/anaconda3/lib/python3.6/site-packages/flask/app.py", line 2292, in wsgi_app
    response = self.full_dispatch_request()
  File "/home/kodi/anaconda3/lib/python3.6/site-packages/flask/app.py", line 1815, in full_dispatch_request
    rv = self.handle_user_exception(e)
  File "/home/kodi/anaconda3/lib/python3.6/site-packages/flask/app.py", line 1718, in handle_user_exception
    reraise(exc_type, exc_value, tb)
  File "/home/kodi/anaconda3/lib/python3.6/site-packages/flask/_compat.py", line 35, in reraise
    raise value
  File "/home/kodi/anaconda3/lib/python3.6/site-packages/flask/app.py", line 1813, in full_dispatch_request
    rv = self.dispatch_request()
  File "/home/kodi/anaconda3/lib/python3.6/site-packages/flask/app.py", line 1799, in dispatch_request
    return self.view_functions[rule.endpoint](**req.view_args)
  File "/home/kodi/anaconda3/lib/python3.6/site-packages/flask_login/utils.py", line 261, in decorated_view
    return func(*args, **kwargs)
  File "/home/kodi/Workspace/openIT/app/admin/routes.py", line 83, in import_category
    initializers=[category_init_func])
  File "/home/kodi/anaconda3/lib/python3.6/site-packages/pyexcel_webio/__init__.py", line 237, in save_book_to_database
    pe.save_book_as(**params)
  File "/home/kodi/anaconda3/lib/python3.6/site-packages/pyexcel/core.py", line 99, in save_book_as
    return sources.save_book(book, **dest_keywords)
  File "/home/kodi/anaconda3/lib/python3.6/site-packages/pyexcel/internal/core.py", line 51, in save_book
    return _save_any(a_source, book)
  File "/home/kodi/anaconda3/lib/python3.6/site-packages/pyexcel/internal/core.py", line 55, in _save_any
    a_source.write_data(instance)
  File "/home/kodi/anaconda3/lib/python3.6/site-packages/pyexcel/plugins/sources/db_sources.py", line 103, in write_data
    **self._keywords)
  File "/home/kodi/anaconda3/lib/python3.6/site-packages/pyexcel/plugins/renderers/sqlalchemy.py", line 56, in render_book_to_stream
    save_data(importer, to_store, file_type=self._file_type, **keywords)
  File "/home/kodi/anaconda3/lib/python3.6/site-packages/pyexcel_io/io.py", line 122, in save_data
    **keywords
  File "/home/kodi/anaconda3/lib/python3.6/site-packages/pyexcel_io/io.py", line 139, in store_data
    writer.write(data)
  File "/home/kodi/anaconda3/lib/python3.6/site-packages/pyexcel_io/book.py", line 217, in write
    sheet_writer = self.create_sheet(sheet_name)
  File "/home/kodi/anaconda3/lib/python3.6/site-packages/pyexcel_io/database/importers/sqlalchemy.py", line 98, in create_sheet
    + "Please be aware of case sensitivity."
Exception: Sheet: Category does not match any given tables.Please be aware of case sensitivity.
2018-07-18 01:14:20,780 INFO: Microblog startup [in /home/kodi/Workspace/openIT/app/__init__.py:66]
2018-07-18 01:15:15,716 ERROR: Exception on /admin/category/import [POST] [in /home/kodi/anaconda3/lib/python3.6/site-packages/flask/app.py:1761]
Traceback (most recent call last):
  File "/home/kodi/anaconda3/lib/python3.6/site-packages/flask/app.py", line 2292, in wsgi_app
    response = self.full_dispatch_request()
  File "/home/kodi/anaconda3/lib/python3.6/site-packages/flask/app.py", line 1815, in full_dispatch_request
    rv = self.handle_user_exception(e)
  File "/home/kodi/anaconda3/lib/python3.6/site-packages/flask/app.py", line 1718, in handle_user_exception
    reraise(exc_type, exc_value, tb)
  File "/home/kodi/anaconda3/lib/python3.6/site-packages/flask/_compat.py", line 35, in reraise
    raise value
  File "/home/kodi/anaconda3/lib/python3.6/site-packages/flask/app.py", line 1813, in full_dispatch_request
    rv = self.dispatch_request()
  File "/home/kodi/anaconda3/lib/python3.6/site-packages/flask/app.py", line 1799, in dispatch_request
    return self.view_functions[rule.endpoint](**req.view_args)
  File "/home/kodi/anaconda3/lib/python3.6/site-packages/flask_login/utils.py", line 261, in decorated_view
    return func(*args, **kwargs)
  File "/home/kodi/Workspace/openIT/app/admin/routes.py", line 83, in import_category
    initializers=[category_init_func])
  File "/home/kodi/anaconda3/lib/python3.6/site-packages/pyexcel_webio/__init__.py", line 237, in save_book_to_database
    pe.save_book_as(**params)
  File "/home/kodi/anaconda3/lib/python3.6/site-packages/pyexcel/core.py", line 99, in save_book_as
    return sources.save_book(book, **dest_keywords)
  File "/home/kodi/anaconda3/lib/python3.6/site-packages/pyexcel/internal/core.py", line 51, in save_book
    return _save_any(a_source, book)
  File "/home/kodi/anaconda3/lib/python3.6/site-packages/pyexcel/internal/core.py", line 55, in _save_any
    a_source.write_data(instance)
  File "/home/kodi/anaconda3/lib/python3.6/site-packages/pyexcel/plugins/sources/db_sources.py", line 103, in write_data
    **self._keywords)
  File "/home/kodi/anaconda3/lib/python3.6/site-packages/pyexcel/plugins/renderers/sqlalchemy.py", line 56, in render_book_to_stream
    save_data(importer, to_store, file_type=self._file_type, **keywords)
  File "/home/kodi/anaconda3/lib/python3.6/site-packages/pyexcel_io/io.py", line 122, in save_data
    **keywords
  File "/home/kodi/anaconda3/lib/python3.6/site-packages/pyexcel_io/io.py", line 139, in store_data
    writer.write(data)
  File "/home/kodi/anaconda3/lib/python3.6/site-packages/pyexcel_io/book.py", line 217, in write
    sheet_writer = self.create_sheet(sheet_name)
  File "/home/kodi/anaconda3/lib/python3.6/site-packages/pyexcel_io/database/importers/sqlalchemy.py", line 98, in create_sheet
    + "Please be aware of case sensitivity."
Exception: Sheet: csv does not match any given tables.Please be aware of case sensitivity.
2018-07-18 01:15:53,276 INFO: Microblog startup [in /home/kodi/Workspace/openIT/app/__init__.py:66]
2018-07-18 01:16:03,109 ERROR: Exception on /admin/category/download [GET] [in /home/kodi/anaconda3/lib/python3.6/site-packages/flask/app.py:1761]
Traceback (most recent call last):
  File "/home/kodi/anaconda3/lib/python3.6/site-packages/flask/app.py", line 2292, in wsgi_app
    response = self.full_dispatch_request()
  File "/home/kodi/anaconda3/lib/python3.6/site-packages/flask/app.py", line 1815, in full_dispatch_request
    rv = self.handle_user_exception(e)
  File "/home/kodi/anaconda3/lib/python3.6/site-packages/flask/app.py", line 1718, in handle_user_exception
    reraise(exc_type, exc_value, tb)
  File "/home/kodi/anaconda3/lib/python3.6/site-packages/flask/_compat.py", line 35, in reraise
    raise value
  File "/home/kodi/anaconda3/lib/python3.6/site-packages/flask/app.py", line 1813, in full_dispatch_request
    rv = self.dispatch_request()
  File "/home/kodi/anaconda3/lib/python3.6/site-packages/flask/app.py", line 1799, in dispatch_request
    return self.view_functions[rule.endpoint](**req.view_args)
  File "/home/kodi/anaconda3/lib/python3.6/site-packages/flask_login/utils.py", line 261, in decorated_view
    return func(*args, **kwargs)
  File "/home/kodi/Workspace/openIT/app/admin/routes.py", line 99, in download_category
    return excel.make_response_from_array([["id", "nom", "description"]], "category", file_name="category")
  File "/home/kodi/anaconda3/lib/python3.6/site-packages/pyexcel_webio/__init__.py", line 370, in make_response_from_array
    file_stream = pe.save_as(array=array, dest_file_type=file_type, **keywords)
  File "/home/kodi/anaconda3/lib/python3.6/site-packages/pyexcel/core.py", line 69, in save_as
    return sources.save_sheet(sheet, **dest_keywords)
  File "/home/kodi/anaconda3/lib/python3.6/site-packages/pyexcel/internal/core.py", line 42, in save_sheet
    a_source = SOURCE.get_writable_source(**keywords)
  File "/home/kodi/anaconda3/lib/python3.6/site-packages/pyexcel/internal/source_plugin.py", line 91, in get_writable_source
    **keywords)
  File "/home/kodi/anaconda3/lib/python3.6/site-packages/pyexcel/internal/source_plugin.py", line 65, in get_a_plugin
    library=source_library, **keywords)
  File "/home/kodi/anaconda3/lib/python3.6/site-packages/pyexcel/internal/source_plugin.py", line 48, in load_me_now
    _error_handler(action, **keywords)
  File "/home/kodi/anaconda3/lib/python3.6/site-packages/pyexcel/internal/source_plugin.py", line 131, in _error_handler
    constants.FILE_TYPE_NOT_SUPPORTED_FMT % (file_type, action))
pyexcel.exceptions.FileTypeNotSupported: File type 'category' is not supported for write.
