2018-07-18 14:13:35,496 ERROR: Exception on /admin/category/export [GET] [in /home/kodi/anaconda3/lib/python3.6/site-packages/flask/app.py:1761]
Traceback (most recent call last):
  File "/home/kodi/anaconda3/lib/python3.6/site-packages/flask/app.py", line 2292, in wsgi_app
    response = self.full_dispatch_request()
  File "/home/kodi/anaconda3/lib/python3.6/site-packages/flask/app.py", line 1815, in full_dispatch_request
    rv = self.handle_user_exception(e)
  File "/home/kodi/anaconda3/lib/python3.6/site-packages/flask/app.py", line 1718, in handle_user_exception
    reraise(exc_type, exc_value, tb)
  File "/home/kodi/anaconda3/lib/python3.6/site-packages/flask/_compat.py", line 35, in reraise
    raise value
  File "/home/kodi/anaconda3/lib/python3.6/site-packages/flask/app.py", line 1813, in full_dispatch_request
    rv = self.dispatch_request()
  File "/home/kodi/anaconda3/lib/python3.6/site-packages/flask/app.py", line 1799, in dispatch_request
    return self.view_functions[rule.endpoint](**req.view_args)
  File "/home/kodi/anaconda3/lib/python3.6/site-packages/flask_login/utils.py", line 261, in decorated_view
    return func(*args, **kwargs)
  File "/home/kodi/Workspace/openIT/app/admin/routes.py", line 93, in export_category
    return excel.make_response_from_query_sets(list, column_names, "csv", file_name="category")
  File "/home/kodi/anaconda3/lib/python3.6/site-packages/pyexcel_webio/__init__.py", line 435, in make_response_from_query_sets
    dest_file_type=file_type, **keywords)
  File "/home/kodi/anaconda3/lib/python3.6/site-packages/pyexcel/core.py", line 68, in save_as
    **sheet_params)
  File "/home/kodi/anaconda3/lib/python3.6/site-packages/pyexcel/sheet.py", line 87, in __init__
    transpose_after=transpose_after
  File "/home/kodi/anaconda3/lib/python3.6/site-packages/pyexcel/sheet.py", line 130, in init
    Matrix.__init__(self, sheet)
  File "/home/kodi/anaconda3/lib/python3.6/site-packages/pyexcel/internal/sheets/matrix.py", line 39, in __init__
    self.__width, self.__array = uniform(list(array))
  File "/home/kodi/anaconda3/lib/python3.6/site-packages/pyexcel_io/database/querysets.py", line 31, in to_array
    for element in SheetReader.to_array(self):
  File "/home/kodi/anaconda3/lib/python3.6/site-packages/pyexcel_io/sheet.py", line 77, in to_array
    self.column_iterator(row)
  File "/home/kodi/anaconda3/lib/python3.6/site-packages/pyexcel_io/database/querysets.py", line 50, in column_iterator
    value = get_simple_attribute(row, column)
  File "/home/kodi/anaconda3/lib/python3.6/site-packages/pyexcel_io/database/querysets.py", line 68, in get_simple_attribute
    value = getattr(row, attribute)
AttributeError: 'Category' object has no attribute 'nom'
2018-07-18 14:14:17,834 INFO: Microblog startup [in /home/kodi/Workspace/openIT/app/__init__.py:66]
2018-07-18 14:16:40,283 ERROR: Exception on /admin/category/import [POST] [in /home/kodi/anaconda3/lib/python3.6/site-packages/flask/app.py:1761]
Traceback (most recent call last):
  File "/home/kodi/anaconda3/lib/python3.6/site-packages/flask/app.py", line 2292, in wsgi_app
    response = self.full_dispatch_request()
  File "/home/kodi/anaconda3/lib/python3.6/site-packages/flask/app.py", line 1815, in full_dispatch_request
    rv = self.handle_user_exception(e)
  File "/home/kodi/anaconda3/lib/python3.6/site-packages/flask/app.py", line 1718, in handle_user_exception
    reraise(exc_type, exc_value, tb)
  File "/home/kodi/anaconda3/lib/python3.6/site-packages/flask/_compat.py", line 35, in reraise
    raise value
  File "/home/kodi/anaconda3/lib/python3.6/site-packages/flask/app.py", line 1813, in full_dispatch_request
    rv = self.dispatch_request()
  File "/home/kodi/anaconda3/lib/python3.6/site-packages/flask/app.py", line 1799, in dispatch_request
    return self.view_functions[rule.endpoint](**req.view_args)
  File "/home/kodi/anaconda3/lib/python3.6/site-packages/flask_login/utils.py", line 261, in decorated_view
    return func(*args, **kwargs)
  File "/home/kodi/Workspace/openIT/app/admin/routes.py", line 83, in import_category
    initializers=[category_init_func])
  File "/home/kodi/anaconda3/lib/python3.6/site-packages/pyexcel_webio/__init__.py", line 237, in save_book_to_database
    pe.save_book_as(**params)
  File "/home/kodi/anaconda3/lib/python3.6/site-packages/pyexcel/core.py", line 99, in save_book_as
    return sources.save_book(book, **dest_keywords)
  File "/home/kodi/anaconda3/lib/python3.6/site-packages/pyexcel/internal/core.py", line 51, in save_book
    return _save_any(a_source, book)
  File "/home/kodi/anaconda3/lib/python3.6/site-packages/pyexcel/internal/core.py", line 55, in _save_any
    a_source.write_data(instance)
  File "/home/kodi/anaconda3/lib/python3.6/site-packages/pyexcel/plugins/sources/db_sources.py", line 103, in write_data
    **self._keywords)
  File "/home/kodi/anaconda3/lib/python3.6/site-packages/pyexcel/plugins/renderers/sqlalchemy.py", line 56, in render_book_to_stream
    save_data(importer, to_store, file_type=self._file_type, **keywords)
  File "/home/kodi/anaconda3/lib/python3.6/site-packages/pyexcel_io/io.py", line 122, in save_data
    **keywords
  File "/home/kodi/anaconda3/lib/python3.6/site-packages/pyexcel_io/io.py", line 139, in store_data
    writer.write(data)
  File "/home/kodi/anaconda3/lib/python3.6/site-packages/pyexcel_io/book.py", line 217, in write
    sheet_writer = self.create_sheet(sheet_name)
  File "/home/kodi/anaconda3/lib/python3.6/site-packages/pyexcel_io/database/importers/sqlalchemy.py", line 98, in create_sheet
    + "Please be aware of case sensitivity."
Exception: Sheet: csv does not match any given tables.Please be aware of case sensitivity.
2018-07-18 14:17:25,493 INFO: Microblog startup [in /home/kodi/Workspace/openIT/app/__init__.py:66]
2018-07-18 14:25:29,612 INFO: Microblog startup [in /home/kodi/Workspace/openIT/app/__init__.py:66]
2018-07-18 14:32:39,080 INFO: Microblog startup [in /home/kodi/Workspace/openIT/app/__init__.py:66]
2018-07-18 14:37:56,853 INFO: Microblog startup [in /home/kodi/Workspace/openIT/app/__init__.py:66]
2018-07-18 14:47:40,249 INFO: Microblog startup [in /home/kodi/Workspace/openIT/app/__init__.py:66]
2018-07-18 14:57:29,947 INFO: Microblog startup [in /home/kodi/Workspace/openIT/app/__init__.py:66]
2018-07-18 15:13:14,831 ERROR: Exception on /equipment/import [POST] [in /home/kodi/anaconda3/lib/python3.6/site-packages/flask/app.py:1761]
Traceback (most recent call last):
  File "/home/kodi/anaconda3/lib/python3.6/site-packages/flask/app.py", line 2292, in wsgi_app
    response = self.full_dispatch_request()
  File "/home/kodi/anaconda3/lib/python3.6/site-packages/flask/app.py", line 1815, in full_dispatch_request
    rv = self.handle_user_exception(e)
  File "/home/kodi/anaconda3/lib/python3.6/site-packages/flask/app.py", line 1718, in handle_user_exception
    reraise(exc_type, exc_value, tb)
  File "/home/kodi/anaconda3/lib/python3.6/site-packages/flask/_compat.py", line 35, in reraise
    raise value
  File "/home/kodi/anaconda3/lib/python3.6/site-packages/flask/app.py", line 1813, in full_dispatch_request
    rv = self.dispatch_request()
  File "/home/kodi/anaconda3/lib/python3.6/site-packages/flask/app.py", line 1799, in dispatch_request
    return self.view_functions[rule.endpoint](**req.view_args)
  File "/home/kodi/anaconda3/lib/python3.6/site-packages/flask_login/utils.py", line 261, in decorated_view
    return func(*args, **kwargs)
  File "/home/kodi/Workspace/openIT/app/home/routes.py", line 124, in import_equipment
    initializers=[equipment_init_func])
  File "/home/kodi/anaconda3/lib/python3.6/site-packages/pyexcel_webio/__init__.py", line 237, in save_book_to_database
    pe.save_book_as(**params)
  File "/home/kodi/anaconda3/lib/python3.6/site-packages/pyexcel/core.py", line 99, in save_book_as
    return sources.save_book(book, **dest_keywords)
  File "/home/kodi/anaconda3/lib/python3.6/site-packages/pyexcel/internal/core.py", line 51, in save_book
    return _save_any(a_source, book)
  File "/home/kodi/anaconda3/lib/python3.6/site-packages/pyexcel/internal/core.py", line 55, in _save_any
    a_source.write_data(instance)
  File "/home/kodi/anaconda3/lib/python3.6/site-packages/pyexcel/plugins/sources/db_sources.py", line 103, in write_data
    **self._keywords)
  File "/home/kodi/anaconda3/lib/python3.6/site-packages/pyexcel/plugins/renderers/sqlalchemy.py", line 56, in render_book_to_stream
    save_data(importer, to_store, file_type=self._file_type, **keywords)
  File "/home/kodi/anaconda3/lib/python3.6/site-packages/pyexcel_io/io.py", line 122, in save_data
    **keywords
  File "/home/kodi/anaconda3/lib/python3.6/site-packages/pyexcel_io/io.py", line 139, in store_data
    writer.write(data)
  File "/home/kodi/anaconda3/lib/python3.6/site-packages/pyexcel_io/book.py", line 219, in write
    sheet_writer.write_array(incoming_dict[sheet_name])
  File "/home/kodi/anaconda3/lib/python3.6/site-packages/pyexcel_io/sheet.py", line 174, in write_array
    self.write_row(row)
  File "/home/kodi/anaconda3/lib/python3.6/site-packages/pyexcel_io/database/importers/sqlalchemy.py", line 44, in write_row
    self._write_row(new_array)
  File "/home/kodi/anaconda3/lib/python3.6/site-packages/pyexcel_io/database/importers/sqlalchemy.py", line 55, in _write_row
    obj = self._native_sheet.row_initializer(row)
  File "/home/kodi/Workspace/openIT/app/home/routes.py", line 109, in equipment_init_func
    c.category_id = row['category.id']
KeyError: 'category.id'
2018-07-18 15:13:51,349 INFO: Microblog startup [in /home/kodi/Workspace/openIT/app/__init__.py:66]
