2018-07-17 17:42:45,312 ERROR: Exception on /handson_view [GET] [in /home/kodi/anaconda3/lib/python3.6/site-packages/flask/app.py:1761]
Traceback (most recent call last):
  File "/home/kodi/anaconda3/lib/python3.6/site-packages/flask/app.py", line 2292, in wsgi_app
    response = self.full_dispatch_request()
  File "/home/kodi/anaconda3/lib/python3.6/site-packages/flask/app.py", line 1815, in full_dispatch_request
    rv = self.handle_user_exception(e)
  File "/home/kodi/anaconda3/lib/python3.6/site-packages/flask/app.py", line 1718, in handle_user_exception
    reraise(exc_type, exc_value, tb)
  File "/home/kodi/anaconda3/lib/python3.6/site-packages/flask/_compat.py", line 35, in reraise
    raise value
  File "/home/kodi/anaconda3/lib/python3.6/site-packages/flask/app.py", line 1813, in full_dispatch_request
    rv = self.dispatch_request()
  File "/home/kodi/anaconda3/lib/python3.6/site-packages/flask/app.py", line 1799, in dispatch_request
    return self.view_functions[rule.endpoint](**req.view_args)
  File "/home/kodi/anaconda3/lib/python3.6/site-packages/flask_login/utils.py", line 261, in decorated_view
    return func(*args, **kwargs)
  File "/home/kodi/Workspace/openIT/app/home/routes.py", line 310, in handson_table
    db.session, [Category], 'home/handsontable.html')
  File "/home/kodi/anaconda3/lib/python3.6/site-packages/pyexcel_webio/__init__.py", line 469, in make_response_from_tables
    dest_file_type=file_type, **keywords)
  File "/home/kodi/anaconda3/lib/python3.6/site-packages/pyexcel/core.py", line 99, in save_book_as
    return sources.save_book(book, **dest_keywords)
  File "/home/kodi/anaconda3/lib/python3.6/site-packages/pyexcel/internal/core.py", line 50, in save_book
    a_source = SOURCE.get_writable_book_source(**keywords)
  File "/home/kodi/anaconda3/lib/python3.6/site-packages/pyexcel/internal/source_plugin.py", line 98, in get_writable_book_source
    **keywords)
  File "/home/kodi/anaconda3/lib/python3.6/site-packages/pyexcel/internal/source_plugin.py", line 65, in get_a_plugin
    library=source_library, **keywords)
  File "/home/kodi/anaconda3/lib/python3.6/site-packages/pyexcel/internal/source_plugin.py", line 48, in load_me_now
    _error_handler(action, **keywords)
  File "/home/kodi/anaconda3/lib/python3.6/site-packages/pyexcel/internal/source_plugin.py", line 131, in _error_handler
    constants.FILE_TYPE_NOT_SUPPORTED_FMT % (file_type, action))
pyexcel.exceptions.FileTypeNotSupported: File type 'home/handsontable.html' is not supported for write.
2018-07-17 17:50:06,254 INFO: Microblog startup [in /home/kodi/Workspace/openIT/app/__init__.py:66]
2018-07-17 17:50:25,307 ERROR: Exception on /admin/category/import [GET] [in /home/kodi/anaconda3/lib/python3.6/site-packages/flask/app.py:1761]
Traceback (most recent call last):
  File "/home/kodi/anaconda3/lib/python3.6/site-packages/flask/app.py", line 2292, in wsgi_app
    response = self.full_dispatch_request()
  File "/home/kodi/anaconda3/lib/python3.6/site-packages/flask/app.py", line 1815, in full_dispatch_request
    rv = self.handle_user_exception(e)
  File "/home/kodi/anaconda3/lib/python3.6/site-packages/flask/app.py", line 1718, in handle_user_exception
    reraise(exc_type, exc_value, tb)
  File "/home/kodi/anaconda3/lib/python3.6/site-packages/flask/_compat.py", line 35, in reraise
    raise value
  File "/home/kodi/anaconda3/lib/python3.6/site-packages/flask/app.py", line 1813, in full_dispatch_request
    rv = self.dispatch_request()
  File "/home/kodi/anaconda3/lib/python3.6/site-packages/flask/app.py", line 1799, in dispatch_request
    return self.view_functions[rule.endpoint](**req.view_args)
  File "/home/kodi/anaconda3/lib/python3.6/site-packages/flask_login/utils.py", line 261, in decorated_view
    return func(*args, **kwargs)
  File "/home/kodi/Workspace/openIT/app/admin/routes.py", line 71, in import_category
    if request.method == 'POST':
NameError: name 'request' is not defined
2018-07-17 17:52:25,410 INFO: Microblog startup [in /home/kodi/Workspace/openIT/app/__init__.py:66]
2018-07-17 17:58:22,466 INFO: Microblog startup [in /home/kodi/Workspace/openIT/app/__init__.py:66]
2018-07-17 18:00:30,030 INFO: Microblog startup [in /home/kodi/Workspace/openIT/app/__init__.py:66]
2018-07-17 18:01:25,475 INFO: Microblog startup [in /home/kodi/Workspace/openIT/app/__init__.py:66]
2018-07-17 18:04:45,162 INFO: Microblog startup [in /home/kodi/Workspace/openIT/app/__init__.py:66]
2018-07-17 18:05:17,577 INFO: Microblog startup [in /home/kodi/Workspace/openIT/app/__init__.py:66]
2018-07-17 20:23:31,660 INFO: Microblog startup [in /home/kodi/Workspace/openIT/app/__init__.py:66]
2018-07-17 20:24:16,390 INFO: Microblog startup [in /home/kodi/Workspace/openIT/app/__init__.py:66]
2018-07-17 20:25:35,656 INFO: Microblog startup [in /home/kodi/Workspace/openIT/app/__init__.py:66]
2018-07-17 20:26:14,607 INFO: Microblog startup [in /home/kodi/Workspace/openIT/app/__init__.py:66]
2018-07-17 20:29:42,475 INFO: Microblog startup [in /home/kodi/Workspace/openIT/app/__init__.py:66]
2018-07-17 20:33:23,120 INFO: Microblog startup [in /home/kodi/Workspace/openIT/app/__init__.py:66]
2018-07-17 20:34:08,071 INFO: Microblog startup [in /home/kodi/Workspace/openIT/app/__init__.py:66]
2018-07-17 20:35:18,906 INFO: Microblog startup [in /home/kodi/Workspace/openIT/app/__init__.py:66]
2018-07-17 20:36:12,820 INFO: Microblog startup [in /home/kodi/Workspace/openIT/app/__init__.py:66]
2018-07-17 20:37:09,157 INFO: Microblog startup [in /home/kodi/Workspace/openIT/app/__init__.py:66]
2018-07-17 20:38:02,094 INFO: Microblog startup [in /home/kodi/Workspace/openIT/app/__init__.py:66]
2018-07-17 20:40:43,551 INFO: Microblog startup [in /home/kodi/Workspace/openIT/app/__init__.py:66]
2018-07-17 20:41:53,926 INFO: Microblog startup [in /home/kodi/Workspace/openIT/app/__init__.py:66]
2018-07-17 20:43:46,423 INFO: Microblog startup [in /home/kodi/Workspace/openIT/app/__init__.py:66]
2018-07-17 20:44:00,486 INFO: Microblog startup [in /home/kodi/Workspace/openIT/app/__init__.py:66]
2018-07-17 20:45:23,262 INFO: Microblog startup [in /home/kodi/Workspace/openIT/app/__init__.py:66]
2018-07-17 20:47:46,170 INFO: Microblog startup [in /home/kodi/Workspace/openIT/app/__init__.py:66]
2018-07-17 20:48:45,550 INFO: Microblog startup [in /home/kodi/Workspace/openIT/app/__init__.py:66]
2018-07-17 21:20:10,971 INFO: Microblog startup [in /home/kodi/Workspace/openIT/app/__init__.py:66]
2018-07-17 21:21:52,987 INFO: Microblog startup [in /home/kodi/Workspace/openIT/app/__init__.py:66]
2018-07-17 21:22:41,664 INFO: Microblog startup [in /home/kodi/Workspace/openIT/app/__init__.py:66]
2018-07-17 21:23:27,677 INFO: Microblog startup [in /home/kodi/Workspace/openIT/app/__init__.py:66]
2018-07-17 21:33:41,505 ERROR: Exception on /admin/label/import [POST] [in /home/kodi/anaconda3/lib/python3.6/site-packages/flask/app.py:1761]
Traceback (most recent call last):
  File "/home/kodi/anaconda3/lib/python3.6/site-packages/flask/app.py", line 2292, in wsgi_app
    response = self.full_dispatch_request()
  File "/home/kodi/anaconda3/lib/python3.6/site-packages/flask/app.py", line 1815, in full_dispatch_request
    rv = self.handle_user_exception(e)
  File "/home/kodi/anaconda3/lib/python3.6/site-packages/flask/app.py", line 1718, in handle_user_exception
    reraise(exc_type, exc_value, tb)
  File "/home/kodi/anaconda3/lib/python3.6/site-packages/flask/_compat.py", line 35, in reraise
    raise value
  File "/home/kodi/anaconda3/lib/python3.6/site-packages/flask/app.py", line 1813, in full_dispatch_request
    rv = self.dispatch_request()
  File "/home/kodi/anaconda3/lib/python3.6/site-packages/flask/app.py", line 1799, in dispatch_request
    return self.view_functions[rule.endpoint](**req.view_args)
  File "/home/kodi/anaconda3/lib/python3.6/site-packages/flask_login/utils.py", line 261, in decorated_view
    return func(*args, **kwargs)
  File "/home/kodi/Workspace/openIT/app/admin/routes.py", line 162, in import_label
    initializers=[label_init_func])
  File "/home/kodi/anaconda3/lib/python3.6/site-packages/pyexcel_webio/__init__.py", line 237, in save_book_to_database
    pe.save_book_as(**params)
  File "/home/kodi/anaconda3/lib/python3.6/site-packages/pyexcel/core.py", line 99, in save_book_as
    return sources.save_book(book, **dest_keywords)
  File "/home/kodi/anaconda3/lib/python3.6/site-packages/pyexcel/internal/core.py", line 51, in save_book
    return _save_any(a_source, book)
  File "/home/kodi/anaconda3/lib/python3.6/site-packages/pyexcel/internal/core.py", line 55, in _save_any
    a_source.write_data(instance)
  File "/home/kodi/anaconda3/lib/python3.6/site-packages/pyexcel/plugins/sources/db_sources.py", line 103, in write_data
    **self._keywords)
  File "/home/kodi/anaconda3/lib/python3.6/site-packages/pyexcel/plugins/renderers/sqlalchemy.py", line 56, in render_book_to_stream
    save_data(importer, to_store, file_type=self._file_type, **keywords)
  File "/home/kodi/anaconda3/lib/python3.6/site-packages/pyexcel_io/io.py", line 122, in save_data
    **keywords
  File "/home/kodi/anaconda3/lib/python3.6/site-packages/pyexcel_io/io.py", line 139, in store_data
    writer.write(data)
  File "/home/kodi/anaconda3/lib/python3.6/site-packages/pyexcel_io/book.py", line 217, in write
    sheet_writer = self.create_sheet(sheet_name)
  File "/home/kodi/anaconda3/lib/python3.6/site-packages/pyexcel_io/database/importers/sqlalchemy.py", line 98, in create_sheet
    + "Please be aware of case sensitivity."
Exception: Sheet: csv does not match any given tables.Please be aware of case sensitivity.
2018-07-17 21:39:20,485 INFO: Microblog startup [in /home/kodi/Workspace/openIT/app/__init__.py:66]
