2018-07-18 15:13:59,611 ERROR: Exception on /equipment/import [POST] [in /home/kodi/anaconda3/lib/python3.6/site-packages/flask/app.py:1761]
Traceback (most recent call last):
  File "/home/kodi/anaconda3/lib/python3.6/site-packages/sqlalchemy/engine/base.py", line 1127, in _execute_context
    context = constructor(dialect, self, conn, *args)
  File "/home/kodi/anaconda3/lib/python3.6/site-packages/sqlalchemy/engine/default.py", line 669, in _init_compiled
    param.append(processors[key](compiled_params[key]))
  File "/home/kodi/anaconda3/lib/python3.6/site-packages/sqlalchemy/dialects/sqlite/base.py", line 610, in process
    raise TypeError("SQLite DateTime type only accepts Python "
TypeError: SQLite DateTime type only accepts Python datetime and date objects as input.

The above exception was the direct cause of the following exception:

Traceback (most recent call last):
  File "/home/kodi/anaconda3/lib/python3.6/site-packages/flask/app.py", line 2292, in wsgi_app
    response = self.full_dispatch_request()
  File "/home/kodi/anaconda3/lib/python3.6/site-packages/flask/app.py", line 1815, in full_dispatch_request
    rv = self.handle_user_exception(e)
  File "/home/kodi/anaconda3/lib/python3.6/site-packages/flask/app.py", line 1718, in handle_user_exception
    reraise(exc_type, exc_value, tb)
  File "/home/kodi/anaconda3/lib/python3.6/site-packages/flask/_compat.py", line 35, in reraise
    raise value
  File "/home/kodi/anaconda3/lib/python3.6/site-packages/flask/app.py", line 1813, in full_dispatch_request
    rv = self.dispatch_request()
  File "/home/kodi/anaconda3/lib/python3.6/site-packages/flask/app.py", line 1799, in dispatch_request
    return self.view_functions[rule.endpoint](**req.view_args)
  File "/home/kodi/anaconda3/lib/python3.6/site-packages/flask_login/utils.py", line 261, in decorated_view
    return func(*args, **kwargs)
  File "/home/kodi/Workspace/openIT/app/home/routes.py", line 124, in import_equipment
    initializers=[equipment_init_func])
  File "/home/kodi/anaconda3/lib/python3.6/site-packages/pyexcel_webio/__init__.py", line 237, in save_book_to_database
    pe.save_book_as(**params)
  File "/home/kodi/anaconda3/lib/python3.6/site-packages/pyexcel/core.py", line 99, in save_book_as
    return sources.save_book(book, **dest_keywords)
  File "/home/kodi/anaconda3/lib/python3.6/site-packages/pyexcel/internal/core.py", line 51, in save_book
    return _save_any(a_source, book)
  File "/home/kodi/anaconda3/lib/python3.6/site-packages/pyexcel/internal/core.py", line 55, in _save_any
    a_source.write_data(instance)
  File "/home/kodi/anaconda3/lib/python3.6/site-packages/pyexcel/plugins/sources/db_sources.py", line 103, in write_data
    **self._keywords)
  File "/home/kodi/anaconda3/lib/python3.6/site-packages/pyexcel/plugins/renderers/sqlalchemy.py", line 56, in render_book_to_stream
    save_data(importer, to_store, file_type=self._file_type, **keywords)
  File "/home/kodi/anaconda3/lib/python3.6/site-packages/pyexcel_io/io.py", line 122, in save_data
    **keywords
  File "/home/kodi/anaconda3/lib/python3.6/site-packages/pyexcel_io/io.py", line 139, in store_data
    writer.write(data)
  File "/home/kodi/anaconda3/lib/python3.6/site-packages/pyexcel_io/book.py", line 220, in write
    sheet_writer.close()
  File "/home/kodi/anaconda3/lib/python3.6/site-packages/pyexcel_io/database/importers/sqlalchemy.py", line 72, in close
    self._native_book.session.commit()
  File "/home/kodi/anaconda3/lib/python3.6/site-packages/sqlalchemy/orm/scoping.py", line 153, in do
    return getattr(self.registry(), name)(*args, **kwargs)
  File "/home/kodi/anaconda3/lib/python3.6/site-packages/sqlalchemy/orm/session.py", line 943, in commit
    self.transaction.commit()
  File "/home/kodi/anaconda3/lib/python3.6/site-packages/sqlalchemy/orm/session.py", line 467, in commit
    self._prepare_impl()
  File "/home/kodi/anaconda3/lib/python3.6/site-packages/sqlalchemy/orm/session.py", line 447, in _prepare_impl
    self.session.flush()
  File "/home/kodi/anaconda3/lib/python3.6/site-packages/sqlalchemy/orm/session.py", line 2254, in flush
    self._flush(objects)
  File "/home/kodi/anaconda3/lib/python3.6/site-packages/sqlalchemy/orm/session.py", line 2380, in _flush
    transaction.rollback(_capture_exception=True)
  File "/home/kodi/anaconda3/lib/python3.6/site-packages/sqlalchemy/util/langhelpers.py", line 66, in __exit__
    compat.reraise(exc_type, exc_value, exc_tb)
  File "/home/kodi/anaconda3/lib/python3.6/site-packages/sqlalchemy/util/compat.py", line 249, in reraise
    raise value
  File "/home/kodi/anaconda3/lib/python3.6/site-packages/sqlalchemy/orm/session.py", line 2344, in _flush
    flush_context.execute()
  File "/home/kodi/anaconda3/lib/python3.6/site-packages/sqlalchemy/orm/unitofwork.py", line 391, in execute
    rec.execute(self)
  File "/home/kodi/anaconda3/lib/python3.6/site-packages/sqlalchemy/orm/unitofwork.py", line 556, in execute
    uow
  File "/home/kodi/anaconda3/lib/python3.6/site-packages/sqlalchemy/orm/persistence.py", line 181, in save_obj
    mapper, table, insert)
  File "/home/kodi/anaconda3/lib/python3.6/site-packages/sqlalchemy/orm/persistence.py", line 866, in _emit_insert_statements
    execute(statement, params)
  File "/home/kodi/anaconda3/lib/python3.6/site-packages/sqlalchemy/engine/base.py", line 948, in execute
    return meth(self, multiparams, params)
  File "/home/kodi/anaconda3/lib/python3.6/site-packages/sqlalchemy/sql/elements.py", line 269, in _execute_on_connection
    return connection._execute_clauseelement(self, multiparams, params)
  File "/home/kodi/anaconda3/lib/python3.6/site-packages/sqlalchemy/engine/base.py", line 1060, in _execute_clauseelement
    compiled_sql, distilled_params
  File "/home/kodi/anaconda3/lib/python3.6/site-packages/sqlalchemy/engine/base.py", line 1132, in _execute_context
    None, None)
  File "/home/kodi/anaconda3/lib/python3.6/site-packages/sqlalchemy/engine/base.py", line 1413, in _handle_dbapi_exception
    exc_info
  File "/home/kodi/anaconda3/lib/python3.6/site-packages/sqlalchemy/util/compat.py", line 265, in raise_from_cause
    reraise(type(exception), exception, tb=exc_tb, cause=cause)
  File "/home/kodi/anaconda3/lib/python3.6/site-packages/sqlalchemy/util/compat.py", line 248, in reraise
    raise value.with_traceback(tb)
  File "/home/kodi/anaconda3/lib/python3.6/site-packages/sqlalchemy/engine/base.py", line 1127, in _execute_context
    context = constructor(dialect, self, conn, *args)
  File "/home/kodi/anaconda3/lib/python3.6/site-packages/sqlalchemy/engine/default.py", line 669, in _init_compiled
    param.append(processors[key](compiled_params[key]))
  File "/home/kodi/anaconda3/lib/python3.6/site-packages/sqlalchemy/dialects/sqlite/base.py", line 610, in process
    raise TypeError("SQLite DateTime type only accepts Python "
sqlalchemy.exc.StatementError: (builtins.TypeError) SQLite DateTime type only accepts Python datetime and date objects as input. [SQL: 'INSERT INTO equipment (category_id, label_id, service_id, model, serial, name, arrived_at, description, created_at, created_by) VALUES (?, ?, ?, ?, ?, ?, ?, ?, ?, ?)'] [parameters: [{'serial': '7M7ZY0J', 'label_id': 32, 'name': 'DELL-ASSURMI1', 'arrived_at': '05/02/2017', 'model': 'VOSTRO 10', 'category_id': 1, 'description': 'Pentium 4', 'created_by': 1, 'service_id': 1, 'created_at': datetime.datetime(2018, 7, 18, 13, 13, 59, 600137)}]]
2018-07-18 15:14:47,582 INFO: Microblog startup [in /home/kodi/Workspace/openIT/app/__init__.py:66]
